<?xml version="1.0" encoding="utf-8"?>
<!-- =================================================================================== -->
<!-- |    This document was autogenerated by xacro from mm.urdf.xacro                  | -->
<!-- |    EDITING THIS FILE BY HAND IS NOT RECOMMENDED                                 | -->
<!-- =================================================================================== -->
<robot name="Thing">
  <material name="dark_grey">
    <color rgba="0.2 0.2 0.2 1.0"/>
  </material>
  <material name="light_grey">
    <color rgba="0.4 0.4 0.4 1.0"/>
  </material>
  <material name="red">
    <color rgba="0.8 0.0 0.0 1.0"/>
  </material>
  <material name="white">
    <color rgba="0.9 0.9 0.9 1.0"/>
  </material>
  <material name="yellow">
    <color rgba="0.8 0.8 0.0 1.0"/>
  </material>
  <material name="black">
    <color rgba="0.15 0.15 0.15 1.0"/>
  </material>
  <material name="seethrough">
    <color rgba="1.0 0.0 0.0 0.5"/>
  </material>

  <link name="front_rocker_link">
    <visual>
      <origin rpy="1.57079632679 0 1.57079632679" xyz="0 0 0"/>
      <geometry>
        <mesh filename="file:///home/adam/phd/code/mm/ocs2_noetic/catkin_ws/src/ocs2_mobile_manipulator_modified/meshes/ridgeback/rocker.stl"/>
      </geometry>
      <material name="black"/>
    </visual>
    <inertial>
      <origin rpy="1.57079632679 0 1.57079632679" xyz="0 0 0"/>
      <mass value="10.267"/>
      <inertia ixx="0.0288" ixy="2.20484e-6" ixz="-1.3145e-5" iyy="0.4324" iyz="1.8944e-3" izz="0.4130"/>
    </inertial>
  </link>
  <joint name="front_rocker" type="fixed">
    <parent link="axle_link"/>
    <child link="front_rocker_link"/>
    <origin rpy="0 0 0" xyz="0.319 0 0"/>
    <axis xyz="1 0 0"/>
    <limit effort="0" lower="-0.08726" upper="0.08726" velocity="0"/>
  </joint>
  <link name="front_left_wheel_link">
    <visual>
      <origin rpy="1.57079632679 0 0" xyz="0 0 0"/>
      <geometry>
        <mesh filename="file:///home/adam/phd/code/mm/ocs2_noetic/catkin_ws/src/ocs2_mobile_manipulator_modified/meshes/ridgeback/wheel.stl"/>
      </geometry>
      <material name="black"/>
    </visual>
    <collision>
      <origin rpy="1.57079632679 0 0" xyz="0 0 0"/>
      <geometry>
        <cylinder length="0.079" radius="0.0759"/>
      </geometry>
    </collision>
    <inertial>
      <origin rpy="0 0 0" xyz="0 0 0"/>
      <mass value="2.3"/>
      <inertia ixx="3.3212e-3" ixy="0" ixz="0" iyy="6.6424e-3" iyz="0" izz="3.3212e-3"/>
    </inertial>
  </link>
  <joint name="front_left_wheel" type="fixed">
    <parent link="front_rocker_link"/>
    <child link="front_left_wheel_link"/>
    <origin rpy="0 0 0" xyz="0 0.2755 0"/>
    <axis xyz="0 1 0"/>
  </joint>
  <link name="front_right_wheel_link">
    <visual>
      <origin rpy="1.57079632679 0 0" xyz="0 0 0"/>
      <geometry>
        <mesh filename="file:///home/adam/phd/code/mm/ocs2_noetic/catkin_ws/src/ocs2_mobile_manipulator_modified/meshes/ridgeback/wheel.stl"/>
      </geometry>
      <material name="black"/>
    </visual>
    <collision>
      <origin rpy="1.57079632679 0 0" xyz="0 0 0"/>
      <geometry>
        <cylinder length="0.079" radius="0.0759"/>
      </geometry>
    </collision>
    <inertial>
      <origin rpy="0 0 0" xyz="0 0 0"/>
      <mass value="2.3"/>
      <inertia ixx="3.3212e-3" ixy="0" ixz="0" iyy="6.6424e-3" iyz="0" izz="3.3212e-3"/>
    </inertial>
  </link>
  <joint name="front_right_wheel" type="fixed">
    <parent link="front_rocker_link"/>
    <child link="front_right_wheel_link"/>
    <origin rpy="0 0 0" xyz="0 -0.2755 0"/>
    <axis xyz="0 1 0"/>
  </joint>
  <link name="rear_rocker_link">
    <visual>
      <origin rpy="1.57079632679 0 1.57079632679" xyz="0 0 0"/>
      <geometry>
        <mesh filename="file:///home/adam/phd/code/mm/ocs2_noetic/catkin_ws/src/ocs2_mobile_manipulator_modified/meshes/ridgeback/rocker.stl"/>
      </geometry>
      <material name="black"/>
    </visual>
    <inertial>
      <origin rpy="1.57079632679 0 1.57079632679" xyz="0 0 0"/>
      <mass value="10.267"/>
      <inertia ixx="0.0288" ixy="2.20484e-6" ixz="-1.3145e-5" iyy="0.4324" iyz="1.8944e-3" izz="0.4130"/>
    </inertial>
  </link>
  <joint name="rear_rocker" type="fixed">
    <parent link="axle_link"/>
    <child link="rear_rocker_link"/>
    <origin rpy="0 0 0" xyz="-0.319 0 0"/>
    <axis xyz="1 0 0"/>
    <limit effort="0" velocity="0"/>
  </joint>
  <link name="rear_left_wheel_link">
    <visual>
      <origin rpy="1.57079632679 0 0" xyz="0 0 0"/>
      <geometry>
        <mesh filename="file:///home/adam/phd/code/mm/ocs2_noetic/catkin_ws/src/ocs2_mobile_manipulator_modified/meshes/ridgeback/wheel.stl"/>
      </geometry>
      <material name="black"/>
    </visual>
    <collision>
      <origin rpy="1.57079632679 0 0" xyz="0 0 0"/>
      <geometry>
        <cylinder length="0.079" radius="0.0759"/>
      </geometry>
    </collision>
    <inertial>
      <origin rpy="0 0 0" xyz="0 0 0"/>
      <mass value="2.3"/>
      <inertia ixx="3.3212e-3" ixy="0" ixz="0" iyy="6.6424e-3" iyz="0" izz="3.3212e-3"/>
    </inertial>
  </link>
  <joint name="rear_left_wheel" type="fixed">
    <parent link="rear_rocker_link"/>
    <child link="rear_left_wheel_link"/>
    <origin rpy="0 0 0" xyz="0 0.2755 0"/>
    <axis xyz="0 1 0"/>
  </joint>
  <link name="rear_right_wheel_link">
    <visual>
      <origin rpy="1.57079632679 0 0" xyz="0 0 0"/>
      <geometry>
        <mesh filename="file:///home/adam/phd/code/mm/ocs2_noetic/catkin_ws/src/ocs2_mobile_manipulator_modified/meshes/ridgeback/wheel.stl"/>
      </geometry>
      <material name="black"/>
    </visual>
    <collision>
      <origin rpy="1.57079632679 0 0" xyz="0 0 0"/>
      <geometry>
        <cylinder length="0.079" radius="0.0759"/>
      </geometry>
    </collision>
    <inertial>
      <origin rpy="0 0 0" xyz="0 0 0"/>
      <mass value="2.3"/>
      <inertia ixx="3.3212e-3" ixy="0" ixz="0" iyy="6.6424e-3" iyz="0" izz="3.3212e-3"/>
    </inertial>
  </link>
  <joint name="rear_right_wheel" type="fixed">
    <parent link="rear_rocker_link"/>
    <child link="rear_right_wheel_link"/>
    <origin rpy="0 0 0" xyz="0 -0.2755 0"/>
    <axis xyz="0 1 0"/>
  </joint>
  <link name="base_link"/>
    <!-- 0.01 z-offset is to match the pyb URDF, which requires a small offset to avoid ground collisions. -->
  <joint name="base_link_joint" type="fixed">
    <origin rpy="0 0 0" xyz="0 0 0.01"/>
    <parent link="base_link"/>
    <child link="chassis_link"/>
  </joint>
  <link name="chassis_link">
    <visual>
      <!-- <origin rpy="0 0 0" xyz="0 0 0.15"/> -->
      <!-- <geometry> -->
      <!--   <box size="1.0 0.8 0.3"/> -->
      <!-- </geometry> -->
      <!-- <origin xyz="0 0 0"/> -->
      <geometry>
        <mesh filename="file:///home/adam/phd/code/mm/ocs2_noetic/catkin_ws/src/ocs2_mobile_manipulator_modified/meshes/ridgeback/body.stl"/>
      </geometry>
      <material name="black"/>
    </visual>
    <collision>
      <!-- simpler collision geometry for speed -->
      <origin rpy="0 0 0" xyz="0 0 0.15"/>
      <geometry>
        <box size="1.0 0.8 0.3"/>
      </geometry>
      <!-- <origin xyz="0 0 0"/> -->
      <!-- <geometry> -->
      <!--   <mesh filename="file:///home/adam/phd/code/mm/ocs2_noetic/catkin_ws/src/ocs2_mobile_manipulator_modified/meshes/ridgeback/body&#45;collision.stl"/> -->
      <!-- </geometry> -->
    </collision>
    <inertial>
      <origin rpy="1.57079632679 0 1.57079632679" xyz="0.012 0.002 0.067"/>
      <!-- <origin rpy="1.57079632679 0 1.57079632679" xyz="0 0 0"/> -->
      <mass value="165.304"/>
      <inertia ixx="4.4744" ixy="0.03098" ixz="0.003647" iyy="7.1624" iyz="0.1228" izz="4.6155"/>
    </inertial>
  </link>
  <joint name="right_side_cover_link_joint" type="fixed">
    <origin rpy="0 0 0" xyz="0 0 0"/>
    <parent link="chassis_link"/>
    <child link="right_side_cover_link"/>
  </joint>
  <joint name="left_side_cover_link_joint" type="fixed">
    <origin rpy="0 0 0" xyz="0 0 0"/>
    <parent link="chassis_link"/>
    <child link="left_side_cover_link"/>
  </joint>
  <link name="left_side_cover_link">
    <visual>
      <origin rpy="0 0 3.14159265359" xyz="0 0 0"/>
      <geometry>
        <mesh filename="file:///home/adam/phd/code/mm/ocs2_noetic/catkin_ws/src/ocs2_mobile_manipulator_modified/meshes/ridgeback/side-cover.stl"/>
      </geometry>
      <material name="yellow"/>
    </visual>
  </link>
  <link name="right_side_cover_link">
    <visual>
      <origin rpy="0 0 0" xyz="0 0 0"/>
      <geometry>
        <mesh filename="file:///home/adam/phd/code/mm/ocs2_noetic/catkin_ws/src/ocs2_mobile_manipulator_modified/meshes/ridgeback/side-cover.stl"/>
      </geometry>
      <material name="yellow"/>
    </visual>
  </link>
  <joint name="front_cover_link_joint" type="fixed">
    <origin rpy="0 0 0" xyz="0 0 0"/>
    <parent link="chassis_link"/>
    <child link="front_cover_link"/>
  </joint>
  <link name="front_cover_link">
    <visual>
      <origin rpy="0 0 0" xyz="0 0 0"/>
      <geometry>
        <mesh filename="file:///home/adam/phd/code/mm/ocs2_noetic/catkin_ws/src/ocs2_mobile_manipulator_modified/meshes/ridgeback/end-cover.stl"/>
      </geometry>
      <material name="black"/>
    </visual>
  </link>
  <joint name="rear_cover_link_joint" type="fixed">
    <origin rpy="0 0 0" xyz="0 0 0"/>
    <parent link="chassis_link"/>
    <child link="rear_cover_link"/>
  </joint>
  <link name="rear_cover_link">
    <visual>
      <origin rpy="0 0 3.14159265359" xyz="0 0 0"/>
      <geometry>
        <mesh filename="file:///home/adam/phd/code/mm/ocs2_noetic/catkin_ws/src/ocs2_mobile_manipulator_modified/meshes/ridgeback/end-cover.stl"/>
      </geometry>
      <material name="black"/>
    </visual>
  </link>
  <joint name="front_lights_link_joint" type="fixed">
    <origin rpy="0 0 0" xyz="0 0 0"/>
    <parent link="chassis_link"/>
    <child link="front_lights_link"/>
  </joint>
  <joint name="rear_lights_link_joint" type="fixed">
    <origin rpy="0 0 0" xyz="0 0 0"/>
    <parent link="chassis_link"/>
    <child link="rear_lights_link"/>
  </joint>
  <link name="front_lights_link">
    <visual>
      <origin rpy="0 0 0" xyz="0 0 0"/>
      <geometry>
        <mesh filename="file:///home/adam/phd/code/mm/ocs2_noetic/catkin_ws/src/ocs2_mobile_manipulator_modified/meshes/ridgeback/lights.stl"/>
      </geometry>
      <material name="white"/>
    </visual>
  </link>
  <link name="rear_lights_link">
    <visual>
      <origin rpy="0 0 3.14159265359" xyz="0 0 0"/>
      <geometry>
        <mesh filename="file:///home/adam/phd/code/mm/ocs2_noetic/catkin_ws/src/ocs2_mobile_manipulator_modified/meshes/ridgeback/lights.stl"/>
      </geometry>
      <material name="red"/>
    </visual>
  </link>
  <joint name="top_link_joint" type="fixed">
    <origin rpy="0 0 0" xyz="0 0 0"/>
    <parent link="chassis_link"/>
    <child link="top_link"/>
  </joint>
  <link name="top_link">
    <visual>
      <origin rpy="0 0 0" xyz="0 0 0"/>
      <geometry>
        <mesh filename="file:///home/adam/phd/code/mm/ocs2_noetic/catkin_ws/src/ocs2_mobile_manipulator_modified/meshes/ridgeback/top.stl"/>
      </geometry>
      <material name="black"/>
    </visual>
    <collision>
      <origin rpy="0 0 0" xyz="0 0 0"/>
      <geometry>
        <mesh filename="file:///home/adam/phd/code/mm/ocs2_noetic/catkin_ws/src/ocs2_mobile_manipulator_modified/meshes/ridgeback/top.stl"/>
      </geometry>
    </collision>
  </link>
  <joint name="axle_joint" type="fixed">
    <origin rpy="0 0 0" xyz="0 0 0.05"/>
    <parent link="chassis_link"/>
    <child link="axle_link"/>
  </joint>
  <link name="axle_link">
    <visual>
      <origin rpy="0 1.57079632679 0" xyz="0 0 0"/>
      <geometry>
        <mesh filename="file:///home/adam/phd/code/mm/ocs2_noetic/catkin_ws/src/ocs2_mobile_manipulator_modified/meshes/ridgeback/axle.stl"/>
      </geometry>
      <material name="black"/>
    </visual>
  </link>
  <link name="imu_link">
    <inertial>
      <mass value="0.001"/>
      <origin rpy="0 0 0" xyz="0 0 0"/>
      <inertia ixx="1e-09" ixy="0.0" ixz="0.0" iyy="1e-09" iyz="0.0" izz="1e-09"/>
    </inertial>
  </link>
  <joint name="imu_joint" type="fixed">
    <parent link="chassis_link"/>
    <child link="imu_link"/>
    <origin rpy="0 0 0" xyz="0.2085 -0.2902 0.1681"/>
  </joint>
  <link name="mid_mount"/>
  <joint name="mid_mount_joint" type="fixed">
    <parent link="base_link"/>
    <child link="mid_mount"/>
    <origin rpy="0 0 0" xyz="0 0 0.28"/>
  </joint>

  <link name="arch_link">
    <visual>
      <geometry>
        <mesh filename="file:///home/adam/phd/code/mm/ocs2_noetic/catkin_ws/src/ocs2_mobile_manipulator_modified/meshes/tor11_mech.dae"/>
      </geometry>
    </visual>
    <!-- <collision> -->
    <!-- 	<geometry> -->
    <!-- 		<mesh filename="package://mm_description/meshes/tor11_mech.dae" /> -->
    <!-- 	</geometry> -->
    <!-- </collision> -->
  </link>
  <joint name="arch_joint" type="fixed">
    <origin rpy="0 0 1.57079632679" xyz="0 0 0.278"/>
    <parent link="top_link"/>
    <child link="arch_link"/>
  </joint>

  <!--
  Author: Kelsey Hawkins
  Contributers: Jimmy Da Silva, Ajit Krisshna N L, Muhammad Asif Rana
-->
  <!-- measured from model -->
  <link name="ur10_arm_base_link">
    <visual>
      <geometry>
        <mesh filename="file:///home/adam/phd/code/mm/ocs2_noetic/catkin_ws/src/ocs2_mobile_manipulator_modified/meshes/ur10/visual/base.dae"/>
      </geometry>
      <material name="LightGrey">
        <color rgba="0.7 0.7 0.7 1.0"/>
      </material>
    </visual>
    <collision>
      <geometry>
        <mesh filename="file:///home/adam/phd/code/mm/ocs2_noetic/catkin_ws/src/ocs2_mobile_manipulator_modified/meshes/ur10/collision/base.stl"/>
      </geometry>
    </collision>
    <inertial>
      <mass value="4.0"/>
      <origin rpy="0 0 0" xyz="0.0 0.0 0.0"/>
      <inertia ixx="0.0061063308908" ixy="0.0" ixz="0.0" iyy="0.0061063308908" iyz="0.0" izz="0.01125"/>
    </inertial>
  </link>
  <joint name="ur10_arm_shoulder_pan_joint" type="revolute">
    <parent link="ur10_arm_base_link"/>
    <child link="ur10_arm_shoulder_link"/>
    <origin rpy="0.0 0.0 0.0" xyz="0.0 0.0 0.1273"/>
    <axis xyz="0 0 1"/>
    <limit effort="330.0" lower="-6.28318530718" upper="6.28318530718" velocity="2.16"/>
    <dynamics damping="0.0" friction="0.0"/>
  </joint>
  <link name="ur10_arm_shoulder_link">
    <visual>
      <geometry>
        <mesh filename="file:///home/adam/phd/code/mm/ocs2_noetic/catkin_ws/src/ocs2_mobile_manipulator_modified/meshes/ur10/visual/shoulder.dae"/>
      </geometry>
      <material name="LightGrey">
        <color rgba="0.7 0.7 0.7 1.0"/>
      </material>
    </visual>
    <collision>
      <geometry>
        <mesh filename="file:///home/adam/phd/code/mm/ocs2_noetic/catkin_ws/src/ocs2_mobile_manipulator_modified/meshes/ur10/collision/shoulder.stl"/>
      </geometry>
    </collision>
    <inertial>
      <mass value="7.778"/>
      <origin rpy="0 0 0" xyz="0.0 0.0 0.0"/>
      <inertia ixx="0.0314743125769" ixy="0.0" ixz="0.0" iyy="0.0314743125769" iyz="0.0" izz="0.021875625"/>
    </inertial>
  </link>
  <joint name="ur10_arm_shoulder_lift_joint" type="revolute">
    <parent link="ur10_arm_shoulder_link"/>
    <child link="ur10_arm_upper_arm_link"/>
    <origin rpy="0.0 1.57079632679 0.0" xyz="0.0 0.220941 0.0"/>
    <axis xyz="0 1 0"/>
    <limit effort="330.0" lower="-6.28318530718" upper="6.28318530718" velocity="2.16"/>
    <dynamics damping="0.0" friction="0.0"/>
  </joint>
  <link name="ur10_arm_upper_arm_link">
    <visual>
      <geometry>
        <mesh filename="file:///home/adam/phd/code/mm/ocs2_noetic/catkin_ws/src/ocs2_mobile_manipulator_modified/meshes/ur10/visual/upperarm.dae"/>
      </geometry>
      <material name="LightGrey">
        <color rgba="0.7 0.7 0.7 1.0"/>
      </material>
    </visual>
    <collision>
      <geometry>
        <mesh filename="file:///home/adam/phd/code/mm/ocs2_noetic/catkin_ws/src/ocs2_mobile_manipulator_modified/meshes/ur10/collision/upperarm.stl"/>
      </geometry>
    </collision>
    <inertial>
      <mass value="12.93"/>
      <origin rpy="0 0 0" xyz="0.0 -0.045 0.306"/>
      <inertia ixx="0.421753803798" ixy="0.0" ixz="0.0" iyy="0.421753803798" iyz="0.0" izz="0.036365625"/>
    </inertial>
  </link>
  <joint name="ur10_arm_elbow_joint" type="revolute">
    <parent link="ur10_arm_upper_arm_link"/>
    <child link="ur10_arm_forearm_link"/>
    <origin rpy="0.0 0.0 0.0" xyz="0.0 -0.1719 0.612"/>
    <axis xyz="0 1 0"/>
    <limit effort="150.0" lower="-3.14159265359" upper="3.14159265359" velocity="3.15"/>
    <dynamics damping="0.0" friction="0.0"/>
  </joint>

  <link name="ur10_arm_forearm_link">
    <visual>
      <geometry>
        <mesh filename="file:///home/adam/phd/code/mm/ocs2_noetic/catkin_ws/src/ocs2_mobile_manipulator_modified/meshes/ur10/visual/forearm.dae"/>
      </geometry>
      <material name="LightGrey">
        <color rgba="0.7 0.7 0.7 1.0"/>
      </material>
    </visual>
    <collision>
      <geometry>
        <mesh filename="file:///home/adam/phd/code/mm/ocs2_noetic/catkin_ws/src/ocs2_mobile_manipulator_modified/meshes/ur10/collision/forearm.stl"/>
      </geometry>
    </collision>
    <inertial>
      <mass value="3.87"/>
      <origin rpy="0 0 0" xyz="0.0 0.0 0.28615"/>
      <inertia ixx="0.111069694097" ixy="0.0" ixz="0.0" iyy="0.111069694097" iyz="0.0" izz="0.010884375"/>
    </inertial>
  </link>
  <joint name="ur10_arm_wrist_1_joint" type="revolute">
    <parent link="ur10_arm_forearm_link"/>
    <child link="ur10_arm_wrist_1_link"/>
    <origin rpy="0.0 1.57079632679 0.0" xyz="0.0 0.0 0.5723"/>
    <axis xyz="0 1 0"/>
    <limit effort="54.0" lower="-6.28318530718" upper="6.28318530718" velocity="3.2"/>
    <dynamics damping="0.0" friction="0.0"/>
  </joint>

  <link name="ur10_arm_wrist_1_link">
    <visual>
      <geometry>
        <mesh filename="file:///home/adam/phd/code/mm/ocs2_noetic/catkin_ws/src/ocs2_mobile_manipulator_modified/meshes/ur10/visual/wrist1.dae"/>
      </geometry>
      <material name="LightGrey">
        <color rgba="0.7 0.7 0.7 1.0"/>
      </material>
    </visual>
    <collision>
      <geometry>
        <mesh filename="file:///home/adam/phd/code/mm/ocs2_noetic/catkin_ws/src/ocs2_mobile_manipulator_modified/meshes/ur10/collision/wrist1.stl"/>
      </geometry>
    </collision>
    <inertial>
      <mass value="1.96"/>
      <origin rpy="0 0 0" xyz="0.0 0.1149 0.0"/>
      <inertia ixx="0.0051082479567" ixy="0.0" ixz="0.0" iyy="0.0051082479567" iyz="0.0" izz="0.0055125"/>
    </inertial>
  </link>

  <joint name="ur10_arm_wrist_2_joint" type="revolute">
    <parent link="ur10_arm_wrist_1_link"/>
    <child link="ur10_arm_wrist_2_link"/>
    <origin rpy="0.0 0.0 0.0" xyz="0.0 0.1149 0.0"/>
    <axis xyz="0 0 1"/>
    <limit effort="54.0" lower="-6.28318530718" upper="6.28318530718" velocity="3.2"/>
    <dynamics damping="0.0" friction="0.0"/>
  </joint>

  <link name="ur10_arm_wrist_2_link">
    <visual>
      <geometry>
        <mesh filename="file:///home/adam/phd/code/mm/ocs2_noetic/catkin_ws/src/ocs2_mobile_manipulator_modified/meshes/ur10/visual/wrist2.dae"/>
      </geometry>
      <material name="LightGrey">
        <color rgba="0.7 0.7 0.7 1.0"/>
      </material>
    </visual>
    <collision>
      <geometry>
        <mesh filename="file:///home/adam/phd/code/mm/ocs2_noetic/catkin_ws/src/ocs2_mobile_manipulator_modified/meshes/ur10/collision/wrist2.stl"/>
      </geometry>
    </collision>
    <inertial>
      <mass value="1.96"/>
      <origin rpy="0 0 0" xyz="0.0 0.0 0.1157"/>
      <inertia ixx="0.0051082479567" ixy="0.0" ixz="0.0" iyy="0.0051082479567" iyz="0.0" izz="0.0055125"/>
    </inertial>
  </link>

  <joint name="ur10_arm_wrist_3_joint" type="revolute">
    <parent link="ur10_arm_wrist_2_link"/>
    <child link="ur10_arm_wrist_3_link"/>
    <origin rpy="0.0 0.0 0.0" xyz="0.0 0.0 0.1157"/>
    <axis xyz="0 1 0"/>
    <limit effort="54.0" lower="-6.28318530718" upper="6.28318530718" velocity="3.2"/>
    <dynamics damping="0.0" friction="0.0"/>
  </joint>

  <link name="ur10_arm_wrist_3_link">
    <visual>
      <geometry>
        <mesh filename="file:///home/adam/phd/code/mm/ocs2_noetic/catkin_ws/src/ocs2_mobile_manipulator_modified/meshes/ur10/visual/wrist3.dae"/>
      </geometry>
      <material name="LightGrey">
        <color rgba="0.7 0.7 0.7 1.0"/>
      </material>
    </visual>
    <collision>
      <geometry>
        <mesh filename="file:///home/adam/phd/code/mm/ocs2_noetic/catkin_ws/src/ocs2_mobile_manipulator_modified/meshes/ur10/collision/wrist3.stl"/>
      </geometry>
    </collision>
    <inertial>
      <mass value="0.202"/>
      <origin rpy="1.57079632679 0 0" xyz="0.0 0.07695 0.0"/>
      <inertia ixx="0.000117921661165" ixy="0.0" ixz="0.0" iyy="0.000117921661165" iyz="0.0" izz="0.000204525"/>
    </inertial>
  </link>

  <joint name="ur10_arm_ee_fixed_joint" type="fixed">
    <parent link="ur10_arm_wrist_3_link"/>
    <child link="ur10_arm_ee_link"/>
    <origin rpy="0.0 0.0 1.57079632679" xyz="0.0 0.0922 0.0"/>
  </joint>

  <link name="ur10_arm_ee_link">
    <collision>
      <geometry>
        <box size="0.01 0.01 0.01"/>
      </geometry>
      <origin rpy="0 0 0" xyz="-0.01 0 0"/>
    </collision>
  </link>

  <!-- ROS base_link to UR 'Base' Coordinates transform -->
  <link name="ur10_arm_base"/>
  <joint name="ur10_arm_base_link-base_fixed_joint" type="fixed">
    <!-- NOTE: this rotation is only needed as long as base_link itself is
                 not corrected wrt the real robot (ie: rotated over 180
                 degrees)
      -->
    <origin rpy="0 0 -3.14159265359" xyz="0 0 0"/>
    <parent link="ur10_arm_base_link"/>
    <child link="ur10_arm_base"/>
  </joint>

  <joint name="ur10_arm_wrist_3_link-tool0_fixed_joint" type="fixed">
    <origin rpy="-1.57079632679 0 0" xyz="0 0.0922 0"/>
    <parent link="ur10_arm_wrist_3_link"/>
    <child link="ur10_arm_tool0"/>
  </joint>

  <!-- Frame coincident with all-zeros TCP on UR controller -->
  <!-- <link name="ur10_arm_tool0"/> -->
  <link name="ur10_arm_tool0">
    <visual>
      <!-- start halfway along the cylinder -->
      <origin rpy="0 0 0" xyz="0 0 0.145"/>
      <geometry>
        <cylinder length="0.290" radius="0.01"/>
      </geometry>
      <material name="black"/>
    </visual>
    <collision>
      <origin rpy="0 0 0" xyz="0 0 0.145"/>
      <geometry>
        <cylinder length="0.290" radius="0.01"/>
      </geometry>
    </collision>
  </link>

  <!-- Join arm -->
  <joint name="ur10_arm_base" type="fixed">
    <parent link="arch_link"/>
    <child link="ur10_arm_base_link"/>
    <origin rpy="0.0 0.0 1.57079632679" xyz="0.01 -0.27 0.375"/>
  </joint>

  <joint name="tool0_tcp_fixed_joint" type="fixed">
    <origin rpy="0.0 0.0 3.14159" xyz="0.0 0.0 0.290"/>
    <parent link="ur10_arm_tool0"/>
    <child link="thing_tool"/>
  </joint>

  <!-- s = 0.3 -->
  <!-- h = 0.08660254037844387 -->
  <!-- r = 0.17320508075688773 -->

  <!-- s = 0.2 -->
  <!-- h = 0.0577 -->
  <!-- r = 0.1155 -->

  <!-- Custom tool for tray balancing -->
  <!-- When oriented forward, the frame has: z forward, x down, y left -->
  <!-- When oriented up (i.e. for balancing): z up, x forward, y left -->
  <link name="thing_tool">
    <visual>
      <origin rpy="0 0 0" xyz="0.1155 0 0"/>
      <geometry>
        <sphere radius="0.02"/>
      </geometry>
      <material name="red"/>
    </visual>

    <visual>
      <origin rpy="0 0 0" xyz="-0.0577 0.1 0"/>
      <geometry>
        <sphere radius="0.02"/>
      </geometry>
      <material name="red"/>
    </visual>

    <visual>
      <origin rpy="0 0 0" xyz="-0.0577 -0.1 0"/>
      <geometry>
        <sphere radius="0.02"/>
      </geometry>
      <material name="red"/>
    </visual>

    <collision>
      <origin rpy="0 0 0" xyz="0.1155 0 0"/>
      <geometry>
        <sphere radius="0.02"/>
      </geometry>
    </collision>

    <collision>
      <origin rpy="0 0 0" xyz="-0.0577 0.1 0"/>
      <geometry>
        <sphere radius="0.02"/>
      </geometry>
    </collision>

    <collision>
      <origin rpy="0 0 0" xyz="-0.0577 -0.1 0"/>
      <geometry>
        <sphere radius="0.02"/>
      </geometry>
    </collision>

    <inertial>
      <origin rpy="0 0 0" xyz="0 0 0"/>
      <mass value="0.1"/>
      <!-- not accurate, but pybullet recomputes this by default -->
      <inertia ixx="1" ixy="0" ixz="0" iyy="1" iyz="0" izz="1"/>
    </inertial>
  </link>

  <!-- Collision element to protect the balanced objects -->
  <link name="balanced_object_collision_link">
    <collision>
      <origin rpy="0 0 0" xyz="0 0 0.07"/>
      <geometry>
        <cylinder length="0.2" radius="0.25"/>
      </geometry>
    </collision>
    <visual>
      <origin rpy="0 0 0" xyz="0 0 0.07"/>
      <geometry>
        <cylinder length="0.2" radius="0.25"/>
      </geometry>
      <material name="seethrough"/>
    </visual>
  </link>
  <joint name="balanced_object_collision_joint" type="fixed">
    <origin rpy="0 0 0" xyz="0 0 0"/>
    <parent link="thing_tool"/>
    <child link="balanced_object_collision_link"/>
  </joint>

  <!-- Collision sphere for the shoulder -->
  <link name="shoulder_collision_link">
    <collision>
      <origin rpy="0 0 0" xyz="0 0 0"/>
      <geometry>
        <sphere radius="0.15"/>
      </geometry>
    </collision>
    <visual>
      <origin rpy="0 0 0" xyz="0 0 0"/>
      <geometry>
        <sphere radius="0.15"/>
      </geometry>
      <material name="seethrough"/>
    </visual>
  </link>
  <joint name="shoulder_collision_joint" type="fixed">
    <origin rpy="0 0 0" xyz="0 0 0"/>
    <parent link="ur10_arm_upper_arm_link"/>
    <child link="shoulder_collision_link"/>
  </joint>

  <!-- Collision cylinder for the upper arm link -->
  <link name="upper_arm_collision_link">
    <collision>
      <origin rpy="0 0 0" xyz="0 -0.05 0.325"/>
      <geometry>
        <cylinder length="0.65" radius="0.06"/>
      </geometry>
    </collision>
    <visual>
      <origin rpy="0 0 0" xyz="0 -0.05 0.325"/>
      <geometry>
        <cylinder length="0.65" radius="0.06"/>
      </geometry>
      <material name="seethrough"/>
    </visual>
  </link>
  <joint name="upper_arm_collision_joint" type="fixed">
    <origin rpy="0 0 0" xyz="0 0 0"/>
    <parent link="ur10_arm_upper_arm_link"/>
    <child link="upper_arm_collision_link"/>
  </joint>

  <!-- Collision sphere for the elbow -->
  <link name="elbow_collision_link">
    <collision>
      <origin rpy="0 0 0" xyz="0 0.06 0"/>
      <geometry>
        <sphere radius="0.15"/>
      </geometry>
    </collision>
    <visual>
      <origin rpy="0 0 0" xyz="0 0.06 0"/>
      <geometry>
        <sphere radius="0.15"/>
      </geometry>
      <material name="seethrough"/>
    </visual>
  </link>
  <joint name="elbow_collision_joint" type="fixed">
    <origin rpy="0 0 0" xyz="0 0 0"/>
    <parent link="ur10_arm_forearm_link"/>
    <child link="elbow_collision_link"/>
  </joint>

  <!-- Collision cylinder for the forearm link -->
  <link name="forearm_collision_link">
    <collision>
      <origin rpy="0 0 0" xyz="0 0 0.3"/>
      <geometry>
        <cylinder length="0.6" radius="0.06"/>
      </geometry>
    </collision>
    <visual>
      <origin rpy="0 0 0" xyz="0 0 0.3"/>
      <geometry>
        <cylinder length="0.6" radius="0.06"/>
      </geometry>
      <material name="seethrough"/>
    </visual>
  </link>
  <joint name="forearm_collision_joint" type="fixed">
    <origin rpy="0 0 0" xyz="0 0 0"/>
    <parent link="ur10_arm_forearm_link"/>
    <child link="forearm_collision_link"/>
  </joint>

  <!-- Collision sphere for the wrist -->
  <link name="wrist_collision_link">
    <collision>
      <origin rpy="0 0 0" xyz="0 0 0"/>
      <geometry>
        <sphere radius="0.15"/>
      </geometry>
    </collision>
    <visual>
      <origin rpy="0 0 0" xyz="0 0 0"/>
      <geometry>
        <sphere radius="0.15"/>
      </geometry>
      <material name="seethrough"/>
    </visual>
  </link>
  <joint name="wrist_collision_joint" type="fixed">
    <origin rpy="0 0 0" xyz="0 0 0"/>
    <parent link="ur10_arm_wrist_3_link"/>
    <child link="wrist_collision_link"/>
  </joint>

  <!-- Collision rectangle for the base -->
  <link name="base_collision_link">
    <visual>
      <origin rpy="0 0 0" xyz="0 0 0.15"/>
      <geometry>
        <box size="1.0 0.8 0.3"/>
      </geometry>
      <material name="seethrough"/>
    </visual>
    <collision>
      <origin rpy="0 0 0" xyz="0 0 0.15"/>
      <geometry>
        <box size="1.0 0.8 0.3"/>
      </geometry>
    </collision>
  </link>
  <joint name="base_collision_joint" type="fixed">
    <origin rpy="0 0 0" xyz="0 0 0.01"/>
    <parent link="base_link"/>
    <child link="base_collision_link"/>
  </joint>

</robot>
